Workbook

Sheet 안내
A1: 101CM 밸런스기획시트 v1.1
A2: 기준 | B2: 기획서 v0.4 (2026-09-29), 결정 기록 (2026-09-28 · 09-29), 본제작 그레이박스 코드 (101CM_Game, 2026-09-30)
A3: 짝 문서 | B3: 101CM 시스템기획서 v1.1 · 101CM 레벨 문서 v0.2
A5: 시트
A6: 조정값 | B6: 모든 조정 수치. ID는 시스템기획서와 코드에서 같은 이름으로 쓴다. '현재 적용값'(G열)이 게임에 들어간 값이다. 값을 바꾸면 G열과 변경기록을 함께 고친다. 삭제된 ID는 맨 아래에 회색으로 남겼다.
A7: 음식종류 | B7: 음식 5종의 증가량과 젤리 크기.
A8: 음식배치 | B8: 구역별 음식 개수 → 합계·누적 길이·90cm 검사. 아래에 개별 음식 목록(ID·좌표·높이)과 프로토타입 배치 비교.
A9: 구역 | B9: 7구역(Z0~Z6)의 범위·역할·위험·구역 안내판·보충 지점·은신처·목표 시간.
A10: 길이별수치 | B10: 길이 10~100cm에서 걷기 속도·청소기 탈출·카메라 거리·꼬리 길이. 레벨 규격을 정할 때 쓴다.
A11: 예고시간점검 | B11: 위험별 예고 시간이 100cm 무리에게도 충분한지 계산한다.
A12: 변경기록 | B12: 값을 바꿀 때마다 날짜·ID·이전 값·새 값·이유를 적는다.
A14: 색 규칙
A15: 파란 글씨 | B15: 직접 넣은 값 (기획서·코드에서 옮긴 값 포함)
A16: 노란 칸 | B16: 고칠 수 있는 입력 칸
A17: 검은 글씨 | B17: 수식. 직접 고치지 않는다
A18: 초록 글씨 | B18: 다른 시트에서 가져온 값
A19: 빨간 칸 | B19: 조정값: 기획서 값과 현재 적용값이 다름 · 검사: 실패
A21: 상태
A22: 확정 | B22: 기획서 v0.4 또는 9/28·9/29 결정으로 정해진 값
A23: 조정 중 | B23: 코드 값을 그대로 쓰고 테스트로 조정할 값
A24: Beta 신규 | B24: Beta에서 새로 만드는 기능의 초기값. 구현 후 실측
A25: 삭제 | B25: v1.1에서 없앤 규칙의 값 (달리기·직원 감지·은신 판정·체크포인트). 참고용으로 남김
A28: 단위 | B28: u = 유닛 = 1타일. 선두 몸 크기 0.6u. cm는 진행 수치이고 월드 거리와 관계없다.
A29: 코드로 옮기기 | B29: 현재는 각 컴포넌트의 public 필드와 레벨 빌더(LevelBuilder.cs)의 씬 값이다('코드 위치' 열). Beta에서 'SO 필드' 열 이름대로 ScriptableObject를 만들고, 시트를 CSV로 내보내 에디터 도구로 ID 기준으로 넣는다.

Sheet 조정값
A1: ID | B1: 시스템 | C1: 항목 | D1: 단위 | E1: 기획서 v0.4 | F1: v1.0 적용값 | G1: 현재 적용값 | H1: 상태 | I1: 코드 위치 (현재) | J1: SO 필드 (Beta) | K1: 비고
A2: 선두 이동
A3: LDR_BODY_SIZE | B3: 선두 | C3: 선두 몸 크기 | D3: u | E3: 0.6 | F3: 0.6 | G3: 0.6 | H3: 확정 | I3: LeaderController.bodySize | J3: GameBalance.leader.bodySize | K3: 1타일 = 1유닛 ≈ 몸길이 1.7배
A4: LDR_WALK_SPEED | B4: 선두 | C4: 걷기 속도 (10cm) | D4: u/s | E4: 2.6 | F4: 2.6 | G4: 2.6 | H4: 확정 | I4: LeaderController.walkSpeed | J4: GameBalance.leader.walkSpeed | K4: 달리기 삭제 후 유일한 이동 속도
A5: LDR_WALK_FACTOR_100 | B5: 선두 | C5: 100cm일 때 걷기 배율 | D5: × | E5: 0.7 | F5: 0.7 | G5: 0.7 | H5: 확정 | I5: LeaderController.slowestWalkFactor | J5: GameBalance.leader.slowestWalkFactor | K5: 100cm 1.82u/s. 10cm → 1에서 선형
A6: LDR_ACCEL | B6: 선두 | C6: 가속도 | D6: u/s² | F6: 18 | G6: 18 | H6: 조정 중 | I6: LeaderController.acceleration | J6: GameBalance.leader.acceleration
A7: 선두 점프 (v1.1 신규)
A8: LDR_JUMP_HEIGHT | B8: 선두 | C8: 점프 높이 (몸 중심 상승) | D8: u | E8: 1.15 | G8: 1.15 | H8: 확정 | I8: LeaderController.jumpHeight | J8: GameBalance.leader.jumpHeight | K8: 1.0u 매대 한 단을 한 번에. 2.0은 두 번
A9: LDR_COYOTE | B9: 선두 | C9: 코요테 타임 | D9: 초 | E9: 0.12 | G9: 0.12 | H9: 확정 | I9: LeaderController.coyoteTime | J9: GameBalance.leader.coyoteTime | K9: 발판을 떠난 직후에도 점프 인정
A10: LDR_JUMP_BUFFER | B10: 선두 | C10: 점프 입력 버퍼 | D10: 초 | E10: 0.15 | G10: 0.15 | H10: 확정 | I10: LeaderController.jumpBuffer | J10: GameBalance.leader.jumpBuffer | K10: 착지 직전 입력을 착지 순간 처리
A11: LDR_FALL_GRAVITY | B11: 선두 | C11: 낙하 중력 배율 | D11: × | E11: 1.7 | G11: 1.7 | H11: 확정 | I11: LeaderController.fallGravityMultiplier | J11: GameBalance.leader.fallGravity | K11: 둥실거리지 않게
A12: 선두 섭취 (발밑 링)
A13: LDR_EAT_RING | B13: 선두 | C13: 발밑 링 반지름 | D13: × 몸 크기 | E13: 0.625 | G13: 0.625 | H13: 확정 | I13: LeaderController.RingRadius (코드 상수) | J13: GameBalance.leader.eatRing | K13: 0.6 × 0.625 = 0.375u. v1.0 LDR_EAT_RANGE 대체
A14: LDR_EAT_MARGIN | B14: 선두 | C14: 링 판정 여유 | D14: u | E14: 0.15 | G14: 0.15 | H14: 확정 | I14: LeaderController.eatRingMargin | J14: GameBalance.leader.eatMargin | K14: 판정 = 수평 거리 ≤ 링 + 여유 (0.525u)
A15: LDR_EAT_HEIGHT | B15: 선두 | C15: 섭취 높이 차 한도 | D15: u | E15: 0.6 | G15: 0.6 | H15: 확정 | I15: LeaderController.eatMaxHeightDiff | J15: GameBalance.leader.eatHeight | K15: 매대 위 음식은 올라가서 먹는다
A16: 선두 충돌·상태
A17: LDR_BOUNCE | B17: 선두 | C17: 자기 몸 충돌 튕김 | D17: 몸길이 | E17: 0.2 | F17: 0.2 | G17: 0.2 | H17: 확정 | I17: LeaderController.bounceBodyLengths | J17: GameBalance.leader.bounce
A18: LDR_BOUNCE_CD | B18: 선두 | C18: 튕김 재발동 간격 | D18: 초 | F18: 0.35 | G18: 0.35 | H18: 조정 중 | I18: LeaderController (코드 상수) | J18: GameBalance.leader.bounceCooldown
A19: LDR_TRAP_RELEASE | B19: 선두 | C19: 자기 몸 갇힘 해제 | D19: 초 | E19: 2 | F19: 2 | G19: 2 | H19: 확정 | I19: LeaderController.trapReleaseTime | J19: GameBalance.leader.trapRelease
A20: LDR_STOMP_STUN | B20: 선두 | C20: 직원 발에 밟혔을 때 기절 | D20: 초 | E20: 1.3 | F20: 1.3 | G20: 1.3 | H20: 확정 | I20: LeaderController.stompStun | J20: GameBalance.leader.stompStun | K20: 9/29 확정: 실패 아님
A21: LDR_STOMP_INVULN | B21: 선두 | C21: 연속 밟힘 보호 | D21: 초 | E21: 3 | F21: 3 | G21: 3 | H21: 확정 | I21: LeaderController.stompInvulnerable | J21: GameBalance.leader.stompInvulnerable
A22: LDR_STOMP_RECOVER_DELAY | B22: 선두 | C22: 선두가 밟힌 뒤 회수 불가 추가 시간 | D22: 초 | F22: 0.8 | G22: 0.8 | H22: 조정 중 | I22: JellyChain.ScatterFrom (코드 상수) | J22: GameBalance.chain.stompRecoverDelay | K22: 회수 가능 시각 = 기절 + 이 값 (약 2.1초)
A23: LDR_FREEZE_SAFE | B23: 선두 | C23: 빙결 후 다시 얼지 않는 시간 | D23: 초 | E23: 3 | G23: 3 | H23: 확정 | I23: LeaderController.TryFreeze (코드 상수) | J23: GameBalance.leader.freezeSafe
A24: LDR_KNOCK_DECEL | B24: 선두 | C24: 밀림 감속 | D24: u/s² | G24: 6 | H24: 조정 중 | I24: LeaderController.knockDecel | J24: GameBalance.leader.knockDecel | K24: 굴러다니는 물건·청소기 탈출
A25: LDR_KNOCK_POP | B25: 선두 | C25: 밀릴 때 튀어 오르는 속도 | D25: u/s | G25: 1.6 | H25: 조정 중 | I25: LeaderController (코드 상수) | J25: GameBalance.leader.knockPop
A26: 청소기 붙잡힘과 탈출 (v1.1 신규)
A27: LDR_ESCAPE_HOLD | B27: 선두 | C27: 이동 키 유지 → 탈출까지 | D27: 초 | E27: 1.8 | G27: 1.8 | H27: 확정 | I27: LeaderController.escapeHoldTime | J27: GameBalance.leader.escapeHold | K27: 연타 없음 (9/29)
A28: LDR_ESCAPE_DECAY | B28: 선두 | C28: 손을 뗄 때 게이지 감소 | D28: /초 | E28: 0.4 | G28: 0.4 | H28: 확정 | I28: LeaderController.escapeDecay | J28: GameBalance.leader.escapeDecay
A29: LDR_ESCAPE_KNOCK | B29: 선두 | C29: 탈출 시 튀어 나가는 속도 | D29: u/s | G29: 6.5 | H29: 조정 중 | I29: LeaderController.EscapeVacuum (코드 상수) | J29: GameBalance.leader.escapeKnock | K29: 누른 방향, 청소기 뒤쪽 성분 제거
A30: LDR_ESCAPE_IMMUNE | B30: 선두 | C30: 탈출 후 다시 끌리지 않는 시간 | D30: 초 | E30: 2 | G30: 2 | H30: 확정 | I30: LeaderController.escapeImmunity | J30: GameBalance.leader.escapeImmunity
A31: 길이와 연결
A32: CHN_LEADER_LEN | B32: 연결 | C32: 선두 길이 | D32: cm | E32: 10 | F32: 10 | G32: 10 | H32: 확정 | I32: JellyChain.LeaderLength (const) | J32: GameBalance.chain.leaderLength
A33: CHN_FOOD_TOTAL | B33: 연결 | C33: 본게임 음식 총량 | D33: cm | E33: 90 | F33: 90 | G33: 90 | H33: 확정 | I33: JellyChain.FoodTotal (const) | J33: GameBalance.chain.foodTotal | K33: 튜토리얼 음식 16cm는 제외
A34: CHN_GOAL | B34: 연결 | C34: 최종 젤리 섭취 조건 | D34: cm | E34: 100 | F34: 100 | G34: 100 | H34: 확정 | I34: JellyChain.Goal (const) | J34: GameBalance.chain.goal
A35: CHN_MAX_UNITS | B35: 연결 | C35: 최대 개체 수 | D35: 마리 | E35: 32 | F35: 32 | G35: 32 | H35: 확정 | I35: (검사 없음) | J35: GameBalance.chain.maxUnits | K35: 선두 + 일반 30 + 최종. 성능 측정 기준
A36: CHN_LOSS_PROTECT | B36: 연결 | C36: 손실 보호 시간 | D36: 초 | E36: 1 | F36: 1 | G36: 1 | H36: 확정 | I36: JellyChain.lossProtection | J36: GameBalance.chain.lossProtection
A37: CHN_RECOVER_PROTECT | B37: 연결 | C37: 회수 직후 보호 | D37: 초 | E37: 0.75 | F37: 0.75 | G37: 0.75 | H37: 확정 | I37: JellyChain.recoverProtection | J37: GameBalance.chain.recoverProtection
A38: CHN_FOLLOW_GAIN | B38: 연결 | C38: 추종 강도 | F38: 10 | G38: 10 | H38: 조정 중 | I38: JellyChain.followGain | J38: GameBalance.chain.followGain
A39: CHN_SPACING | B39: 연결 | C39: 젤리 간격 계수 | D39: × | F39: 1.08 | G39: 1.08 | H39: 조정 중 | I39: JellyChain.spacingFactor | J39: GameBalance.chain.spacing | K39: 간격 = (앞 반지름 + 뒤 반지름) × 값. 수평 거리
A40: CHN_FALLBACK | B40: 연결 | C40: 경로 이탈 허용 거리 | D40: u | E40: 2.5 | F40: 2.5 | G40: 2.5 | H40: 확정 | I40: JellyChain.fallbackDistance | J40: GameBalance.chain.fallbackDistance | K40: 넘으면 바로 앞 젤리를 향한다
...

Sheet 음식종류
A1: 종류 ID | B1: 이름 | C1: 증가량 (cm) | D1: 젤리 크기 (u) | E1: 젤리 반지름 (u) | F1: 연결 젤리 외형 | G1: 배치 지침
A2: Fruit | B2: 과일 조각 | C2: 3 | D2: =INDEX(조정값!$G$2:$G$170,MATCH("JLY_SIZE_BASE",조정값!$A$2:$A$170,0))+INDEX(조정값!$G$2:$G$170,MATCH("JLY_SIZE_PER_CM",조정값!$A$2:$A$170,0))*C2 -> 0.435 | E2: =D2/2 -> 0.2175 | F2: 과일색 몸체와 작은 잎 장식. 색 변형 3종(빨강·주황·초록) | G2: 가장 흔함. 초반과 위험 근처 미끼
A3: Bread | B3: 빵 조각 | C3: 4 | D3: =INDEX(조정값!$G$2:$G$170,MATCH("JLY_SIZE_BASE",조정값!$A$2:$A$170,0))+INDEX(조정값!$G$2:$G$170,MATCH("JLY_SIZE_PER_CM",조정값!$A$2:$A$170,0))*C3 -> 0.46 | E3: =D3/2 -> 0.23 | F3: 노란색·갈색 몸체와 둥근 토핑
A4: Cheese | B4: 치즈 조각 | C4: 5 | D4: =INDEX(조정값!$G$2:$G$170,MATCH("JLY_SIZE_BASE",조정값!$A$2:$A$170,0))+INDEX(조정값!$G$2:$G$170,MATCH("JLY_SIZE_PER_CM",조정값!$A$2:$A$170,0))*C4 -> 0.485 | E4: =D4/2 -> 0.2425 | F4: 노란색 몸체와 치즈 무늬 | G4: 유제품 구역 중심
A5: Cookie | B5: 쿠키 | C5: 6 | D5: =INDEX(조정값!$G$2:$G$170,MATCH("JLY_SIZE_BASE",조정값!$A$2:$A$170,0))+INDEX(조정값!$G$2:$G$170,MATCH("JLY_SIZE_PER_CM",조정값!$A$2:$A$170,0))*C5 -> 0.51 | E5: =D5/2 -> 0.255 | F5: 갈색 몸체와 초코칩 무늬 | G5: 과자 구역 중심
A6: Cake | B6: 케이크 조각 | C6: 8 | D6: =INDEX(조정값!$G$2:$G$170,MATCH("JLY_SIZE_BASE",조정값!$A$2:$A$170,0))+INDEX(조정값!$G$2:$G$170,MATCH("JLY_SIZE_PER_CM",조정값!$A$2:$A$170,0))*C6 -> 0.56 | E6: =D6/2 -> 0.28 | F6: 크림색 몸체와 딸기 장식 | G6: 드물게. 한 판 1개
A8: 증가량(C열)은 기획서 03장 값이다. 바꾸면 음식배치 시트 합계와 90cm 검사가 함께 바뀐다.

Sheet 구역
A1: 구역 | B1: 이름 | C1: 역할 | D1: 새 위험 | E1: 다시 나오는 위험 | F1: 구역 안내판 | G1: 보충 지점 | H1: 은신처 | I1: 목표 시간 (분) | J1: 음식 (cm) | K1: 입장 길이 | L1: 퇴장 길이 | M1: 크기 (타일) | N1: 범위 (x, z)
A2: Z0 | B2: 창고 (튜토리얼) | C2: 이동·시점·먹기·점프·기분 표현 학습 | D2: — | E2: — | F2: (없음) | G2: (없음) | H2: 연습 바구니 1 | J2: =음식배치!I6 -> 16 | K2: — | L2: 10 (초기화) | M2: 10×13 | N2: 0~10, 0~13
A3: Z1 | B3: 과일·야채 | C3: 꼬리 경로와 쉬운 먹기 | D3: 굴러다니는 과일, 과일 무더기 | E3: — | F3: ZS1 | G3: SP1 | H3: 작은 1 | J3: =음식배치!I7 -> 16 | K3: =음식배치!L7 -> 10 | L3: =음식배치!M7 -> 26 | M3: 24×13 | N3: 10~34, 0~13
A4: Z2 | B4: 과자 코너 | C4: 세일 붕괴와 경로 선택 | D4: 세일 매대 붕괴 (5곳) | E4: — | F4: ZS2 | G4: SP2 | H4: 작은 2 | J4: =음식배치!I8 -> 20 | K4: =음식배치!L8 -> 26 | L4: =음식배치!M8 -> 46 | M4: 17×14 | N4: 17~34, 13~27
A5: Z3 | B5: 음료·유제품 | C5: 직원 사이 횡단, 청소기 첫 등장 | D5: 직원 발, 쏟은 음료, 청소기 | E5: 굴러다니는 캔, 세일 매대 1 | F5: ZS3 | G5: SP3 | H5: 긴 1 + 작은 1 | J5: =음식배치!I9 -> 20 | K5: =음식배치!L9 -> 46 | L5: =음식배치!M9 -> 66 | M5: 17×14 | N5: 0~17, 13~27
A6: Z4 | B6: 아이스크림 | C6: 청소기와 바닥 방해 | D6: 녹은 아이스크림, 얼음 | E6: 청소기 2, 직원 1 | F6: ZS4 | G6: SP4 | H6: 긴 1 | J6: =음식배치!I10 -> 19 | K6: =음식배치!L10 -> 66 | L6: =음식배치!M10 -> 85 | M6: 14×14 | N6: 0~14, 27~41
A7: Z5 | B7: 카운터 | C7: 모든 위험 조합 | D7: 계산대 벨트 | E7: 세일 2, 직원, 청소기, 굴러다니는 물건, 미끄럼, 끈적, 얼음 | F7: ZS5 | G7: SP5 | H7: 긴 1 | J7: =음식배치!I11 -> 15 | K7: =음식배치!L11 -> 85 | L7: =음식배치!M11 -> 100 | M7: 14×14 | N7: 14~28, 27~41
A8: Z6 | B8: 출구 (골 홀) | C8: 마지막 1cm와 엔딩 | D8: — | E8: — (위험 없음) | F8: (골 게이트) | G8: (없음) | H8: — | J8: 최종 1cm | K8: =L7 -> 100 | L8: =IF(ISNUMBER(K8),K8+1,"101") -> 101 | M8: 6×14 | N8: 28~34, 27~41
B9: 합계 | I9: =SUM(I2:I8) -> 0 | J9: =SUM(J3:J7) -> 90
B10: 목표 시간 검사 | I10: =IF(COUNT(I3:I7)<5,"재측정 필요",IF(ISNUMBER(INDEX(조정값!$G$2:$G$170,MATCH("GAM_PLAYTIME",조정값!$A$2:$A$170,0))),IF(I9=INDEX(조정값!$G$2:$G$170,MATCH("GAM_PLAYTIME",조정값!$A$2:$A$170,0)),"OK","합계 "&I9&"분"),"합계 "&I9&"분")) -> 재측정 필요
A12: 음식(cm)·입장·퇴장 길이는 음식배치 시트에서 자동으로 가져온다(초록). 목표 시간(I열, 노란 칸)은 34×41 맵으로 줄인 뒤 다시 재서 넣는다. 창고 음식은 튜토리얼 전용이라 본게임 합계에서 빠진다.
A13: 위험 마커 총 34개: Z1 2 · Z2 5 · Z3 9 · Z4 8 · Z5 10 · Z6 0. 상세 좌표는 레벨 문서 v0.2.

Sheet 음식배치
A1: A. 배치 (그레이박스 Level_Main, 7구역)
A2: 노란 칸(개수·목표)만 고친다. 증가량은 음식종류 시트에서 가져온다.
A4: 구역 | B4: 이름 | C4: 3cm | D4: 4cm | E4: 5cm | F4: 6cm | G4: 8cm | H4: 개수 | I4: 합계 (cm) | J4: 목표 (cm) | K4: 차이 | L4: 입장 길이 | M4: 퇴장 길이 | N4: 목록 합계 검사
B5: 증가량 (cm) | C5: =음식종류!C2 -> 3 | D5: =음식종류!C3 -> 4 | E5: =음식종류!C4 -> 5 | F5: =음식종류!C5 -> 6 | G5: =음식종류!C6 -> 8
A6: Z0 | B6: 창고 (튜토리얼) | C6: 2 | D6: 1 | E6: 0 | F6: 1 | G6: 0 | H6: =SUM(C6:G6) -> 4 | I6: =SUMPRODUCT(C6:G6,$C$5:$G$5) -> 16 | J6: 16 | K6: =I6-J6 -> 0 | L6: — | M6: (초기화) | N6: =IF(SUMIF($B$28:$B$54,A6,$D$28:$D$54)=I6,"OK","목록 불일치") -> OK
A7: Z1 | B7: 과일·야채 | C7: 4 | D7: 1 | E7: 0 | F7: 0 | G7: 0 | H7: =SUM(C7:G7) -> 5 | I7: =SUMPRODUCT(C7:G7,$C$5:$G$5) -> 16 | J7: 16 | K7: =I7-J7 -> 0 | L7: =INDEX(조정값!$G$2:$G$170,MATCH("CHN_LEADER_LEN",조정값!$A$2:$A$170,0)) -> 10 | M7: =L7+I7 -> 26 | N7: =IF(SUMIF($B$28:$B$54,A7,$D$28:$D$54)=I7,"OK","목록 불일치") -> OK
A8: Z2 | B8: 과자 코너 | C8: 2 | D8: 2 | E8: 0 | F8: 1 | G8: 0 | H8: =SUM(C8:G8) -> 5 | I8: =SUMPRODUCT(C8:G8,$C$5:$G$5) -> 20 | J8: 20 | K8: =I8-J8 -> 0 | L8: =M7 -> 26 | M8: =L8+I8 -> 46 | N8: =IF(SUMIF($B$28:$B$54,A8,$D$28:$D$54)=I8,"OK","목록 불일치") -> OK
A9: Z3 | B9: 음료·유제품 | C9: 2 | D9: 1 | E9: 2 | F9: 0 | G9: 0 | H9: =SUM(C9:G9) -> 5 | I9: =SUMPRODUCT(C9:G9,$C$5:$G$5) -> 20 | J9: 20 | K9: =I9-J9 -> 0 | L9: =M8 -> 46 | M9: =L9+I9 -> 66 | N9: =IF(SUMIF($B$28:$B$54,A9,$D$28:$D$54)=I9,"OK","목록 불일치") -> OK
A10: Z4 | B10: 아이스크림 | C10: 1 | D10: 2 | E10: 0 | F10: 0 | G10: 1 | H10: =SUM(C10:G10) -> 4 | I10: =SUMPRODUCT(C10:G10,$C$5:$G$5) -> 19 | J10: 19 | K10: =I10-J10 -> 0 | L10: =M9 -> 66 | M10: =L10+I10 -> 85 | N10: =IF(SUMIF($B$28:$B$54,A10,$D$28:$D$54)=I10,"OK","목록 불일치") -> OK
A11: Z5 | B11: 카운터 | C11: 2 | D11: 1 | E11: 1 | F11: 0 | G11: 0 | H11: =SUM(C11:G11) -> 4 | I11: =SUMPRODUCT(C11:G11,$C$5:$G$5) -> 15 | J11: 15 | K11: =I11-J11 -> 0 | L11: =M10 -> 85 | M11: =L11+I11 -> 100 | N11: =IF(SUMIF($B$28:$B$54,A11,$D$28:$D$54)=I11,"OK","목록 불일치") -> OK
B12: 본게임 합계 (Z1~Z5) | C12: =SUM(C7:C11) -> 11 | D12: =SUM(D7:D11) -> 7 | E12: =SUM(E7:E11) -> 3 | F12: =SUM(F7:F11) -> 1 | G12: =SUM(G7:G11) -> 1 | H12: =SUM(H7:H11) -> 23 | I12: =SUM(I7:I11) -> 90 | J12: =SUM(J7:J11) -> 90 | K12: =I12-J12 -> 0
A14: 검사
A15: 본게임 음식 합계 = 90cm | E15: =IF(I12=INDEX(조정값!$G$2:$G$170,MATCH("CHN_FOOD_TOTAL",조정값!$A$2:$A$170,0)),"OK","합계 오류: "&I12&"cm") -> OK
A16: 음식 개수 18~30개 | E16: =IF(AND(H12>=18,H12<=30),"OK","개수 범위 밖: "&H12&"개") -> OK
A17: 모두 먹으면 정확히 100cm | E17: =IF(M11=INDEX(조정값!$G$2:$G$170,MATCH("CHN_GOAL",조정값!$A$2:$A$170,0)),"OK","최종 길이 "&M11&"cm") -> OK
A18: 최대 일반 젤리 ≤ 30마리 | E18: =IF(H12<=30,"OK","초과") -> OK
A19: 평균 증가량 3~5cm | E19: =IF(AND(I12/H12>=3,I12/H12<=5),"OK","범위 밖") -> OK
A20: 평균 증가량 (cm) | E20: =I12/H12 -> 3.9130435
A21: 높은 곳 음식 (점프 필요) | E21: =COUNTIFS($B$32:$B$54,"<>Z0",$K$32:$K$54,">0") -> 9 | H21: 개 (창고 연습 1개 별도)
A26: B. 개별 음식 목록 (Level_Main 배치 = 레벨 문서 v0.2)
A27: 음식 ID | B27: 구역 | C27: 종류 | D27: cm | E27: 위치 메모 | H27: 위험 근처 | I27: 상태 | J27: x | K27: 높이 (u) | L27: z
A28: F-Z0-01 | B28: Z0 | C28: Fruit | D28: =INDEX(음식종류!$C$2:$C$6,MATCH(C28,음식종류!$A$2:$A$6,0)) -> 3 | E28: 출발 지점 앞 바닥 | I28: 검증됨 | J28: 2.5 | K28: 0 | L28: 5
A29: F-Z0-02 | B29: Z0 | C29: Fruit | D29: =INDEX(음식종류!$C$2:$C$6,MATCH(C29,음식종류!$A$2:$A$6,0)) -> 3 | E29: 팔레트 아래 | I29: 검증됨 | J29: 5.5 | K29: 0 | L29: 2.6
A30: F-Z0-03 | B30: Z0 | C30: Bread | D30: =INDEX(음식종류!$C$2:$C$6,MATCH(C30,음식종류!$A$2:$A$6,0)) -> 4 | E30: 점프 연습 상자(0.5 → 1.0) 위 | I30: 검증됨 | J30: 8.1 | K30: 1 | L30: 9.5
A31: F-Z0-04 | B31: Z0 | C31: Cookie | D31: =INDEX(음식종류!$C$2:$C$6,MATCH(C31,음식종류!$A$2:$A$6,0)) -> 6 | E31: 연습용 바구니 안 | I31: 검증됨 | J31: 1.5 | K31: 0 | L31: 9.7
A32: F-Z1-01 | B32: Z1 | C32: Fruit | D32: =INDEX(음식종류!$C$2:$C$6,MATCH(C32,음식종류!$A$2:$A$6,0)) -> 3 | E32: 입구 바닥 (쉬움) | I32: 검증됨 | J32: 12.8 | K32: 0 | L32: 2.8
A33: F-Z1-02 | B33: Z1 | C33: Fruit | D33: =INDEX(음식종류!$C$2:$C$6,MATCH(C33,음식종류!$A$2:$A$6,0)) -> 3 | E33: 진열 테이블 위 (점프) | I33: 검증됨 | J33: 16.2 | K33: 0.95 | L33: 9.5
A34: F-Z1-03 | B34: Z1 | C34: Fruit | D34: =INDEX(음식종류!$C$2:$C$6,MATCH(C34,음식종류!$A$2:$A$6,0)) -> 3 | E34: 테이블 아래 | I34: 검증됨 | J34: 22 | K34: 0 | L34: 3.5
A35: F-Z1-04 | B35: Z1 | C35: Fruit | D35: =INDEX(음식종류!$C$2:$C$6,MATCH(C35,음식종류!$A$2:$A$6,0)) -> 3 | E35: 과일 무더기 레인 옆 | H35: 예 | I35: 검증됨 | J35: 24.5 | K35: 0 | L35: 10.4
A36: F-Z1-05 | B36: Z1 | C36: Bread | D36: =INDEX(음식종류!$C$2:$C$6,MATCH(C36,음식종류!$A$2:$A$6,0)) -> 4 | E36: 과일 언덕 꼭대기 (0.5 → 1.0) | I36: 검증됨 | J36: 28 | K36: 1 | L36: 6.4
A37: F-Z2-01 | B37: Z2 | C37: Fruit | D37: =INDEX(음식종류!$C$2:$C$6,MATCH(C37,음식종류!$A$2:$A$6,0)) -> 3 | E37: 북쪽 통로 (바깥길) | I37: 검증됨 | J37: 26.4 | K37: 0 | L37: 24.75
A38: F-Z2-02 | B38: Z2 | C38: Fruit | D38: =INDEX(음식종류!$C$2:$C$6,MATCH(C38,음식종류!$A$2:$A$6,0)) -> 3 | E38: 중앙 행사 매대 위 (붕괴 두 곳 사이) | H38: 예 | I38: 검증됨 | J38: 24.9 | K38: 1 | L38: 20
A39: F-Z2-03 | B39: Z2 | C39: Bread | D39: =INDEX(음식종류!$C$2:$C$6,MATCH(C39,음식종류!$A$2:$A$6,0)) -> 4 | E39: 카트 아래 | I39: 검증됨 | J39: 30.1 | K39: 0 | L39: 18.2
A40: F-Z2-04 | B40: Z2 | C40: Bread | D40: =INDEX(음식종류!$C$2:$C$6,MATCH(C40,음식종류!$A$2:$A$6,0)) -> 4 | E40: 엔드캡 바구니 안 | I40: 검증됨 | J40: 21.8 | K40: 0 | L40: 16.8
A41: F-Z2-05 | B41: Z2 | C41: Cookie | D41: =INDEX(음식종류!$C$2:$C$6,MATCH(C41,음식종류!$A$2:$A$6,0)) -> 6 | E41: 계단 진열대 꼭대기 (점프 2번) | I41: 검증됨 | J41: 33.35 | K41: 2 | L41: 20
A42: F-Z3-01 | B42: Z3 | C42: Fruit | D42: =INDEX(음식종류!$C$2:$C$6,MATCH(C42,음식종류!$A$2:$A$6,0)) -> 3 | E42: 냉장고 옆 구석 | I42: 검증됨 | J42: 15.2 | K42: 0 | L42: 16.6
A43: F-Z3-02 | B43: Z3 | C43: Fruit | D43: =INDEX(음식종류!$C$2:$C$6,MATCH(C43,음식종류!$A$2:$A$6,0)) -> 3 | E43: 은신 통로 입구 앞 | I43: 검증됨 | J43: 2.1 | K43: 0 | L43: 16.4
A44: F-Z3-03 | B44: Z3 | C44: Bread | D44: =INDEX(음식종류!$C$2:$C$6,MATCH(C44,음식종류!$A$2:$A$6,0)) -> 4 | E44: 직원 순찰 안쪽 | H44: 예 | I44: 검증됨 | J44: 12.4 | K44: 0 | L44: 21.6
A45: F-Z3-04 | B45: Z3 | C45: Cheese | D45: =INDEX(음식종류!$C$2:$C$6,MATCH(C45,음식종류!$A$2:$A$6,0)) -> 5 | E45: 긴 은신 통로 가운데 | I45: 검증됨 | J45: 7.1 | K45: 0 | L45: 14.15
A46: F-Z3-05 | B46: Z3 | C46: Cheese | D46: =INDEX(음식종류!$C$2:$C$6,MATCH(C46,음식종류!$A$2:$A$6,0)) -> 5 | E46: 음료 팔레트 꼭대기 (점프 2번) | H46: 예 | I46: 검증됨 | J46: 7.4 | K46: 2 | L46: 20.5
...

Sheet 길이별수치
A1: 길이별 이동·청소기 탈출·카메라·꼬리 길이
A2: 모든 값은 조정값 시트의 '현재 적용값'과 음식배치 시트의 평균 증가량으로 계산한다. 레벨 규격(통로 폭, 은신처 크기, 청소기 배치)을 정할 때 쓴다.
A4: 평균 증가량 (cm) | B4: =음식배치!E20 -> 3.9130435 | D4: 걷기 속도 10cm | E4: =INDEX(조정값!$G$2:$G$170,MATCH("LDR_WALK_SPEED",조정값!$A$2:$A$170,0)) -> 2.6 | G4: cm당 거리 | H4: =INDEX(조정값!$G$2:$G$170,MATCH("CAM_DIST_PER_CM",조정값!$A$2:$A$170,0)) -> 0.05
A5: 평균 젤리 반지름 (u) | B5: =(INDEX(조정값!$G$2:$G$170,MATCH("JLY_SIZE_BASE",조정값!$A$2:$A$170,0))+INDEX(조정값!$G$2:$G$170,MATCH("JLY_SIZE_PER_CM",조정값!$A$2:$A$170,0))*B4)/2 -> 0.22891304 | D5: 100cm 걷기 배율 | E5: =INDEX(조정값!$G$2:$G$170,MATCH("LDR_WALK_FACTOR_100",조정값!$A$2:$A$170,0)) -> 0.7 | G5: 카메라 최대 거리 | H5: =INDEX(조정값!$G$2:$G$170,MATCH("CAM_MAX_DIST",조정값!$A$2:$A$170,0)) -> 7.5
A6: 선두 반지름 (u) | B6: =INDEX(조정값!$G$2:$G$170,MATCH("LDR_BODY_SIZE",조정값!$A$2:$A$170,0))/2 -> 0.3 | D6: 청소기 최대 끌림 | E6: =INDEX(조정값!$G$2:$G$170,MATCH("VAC_LEADER_PULL_MAX",조정값!$A$2:$A$170,0)) -> 2.3 | G6: 선두 길이 | H6: =INDEX(조정값!$G$2:$G$170,MATCH("CHN_LEADER_LEN",조정값!$A$2:$A$170,0)) -> 10
A7: 젤리 간격 계수 | B7: =INDEX(조정값!$G$2:$G$170,MATCH("CHN_SPACING",조정값!$A$2:$A$170,0)) -> 1.08 | D7: 흡입 영역 길이 | E7: =INDEX(조정값!$G$2:$G$170,MATCH("VAC_ZONE_L",조정값!$A$2:$A$170,0)) -> 2.4 | G7: 목표 길이 | H7: =INDEX(조정값!$G$2:$G$170,MATCH("CHN_GOAL",조정값!$A$2:$A$170,0)) -> 100
D8: 카메라 기본 거리 | E8: =INDEX(조정값!$G$2:$G$170,MATCH("CAM_BASE_DIST",조정값!$A$2:$A$170,0)) -> 3.2
A10: 길이 (cm) | B10: 감속 배율 | C10: 걷기 (u/s) | D10: 걷기 − 최대 끌림 (u/s) | E10: 흡입 영역을 걸어서 벗어나기 (초) | F10: 카메라 거리 (u) | G10: 예상 연결 수 (마리) | H10: 꼬리 길이 (u) | I10: 10타일 걷기 (초) | J10: 꼬리가 한 지점을 지나는 시간 · 걷기 (초)
A11: 10 | B11: =1+($E$5-1)*(A11-$H$6)/($H$7-$H$6) -> 1 | C11: =$E$4*B11 -> 2.6 | D11: =C11-$E$6 -> 0.3 | E11: =IF(D11>0,$E$7/D11,"못 벗어남 · 점프") -> 8 | F11: =MIN($H$5,$E$8+(A11-$H$6)*$H$4) -> 3.2 | G11: =(A11-$H$6)/$B$4 -> 0 | H11: =IF(G11<=0,$B$6,($B$6+$B$5)*$B$7+MAX(0,G11-1)*2*$B$5*$B$7+$B$5) -> 0.3 | I11: =10/C11 -> 3.8461538 | J11: =H11/C11 -> 0.11538462
A12: 15 | B12: =1+($E$5-1)*(A12-$H$6)/($H$7-$H$6) -> 0.98333333 | C12: =$E$4*B12 -> 2.5566667 | D12: =C12-$E$6 -> 0.25666667 | E12: =IF(D12>0,$E$7/D12,"못 벗어남 · 점프") -> 9.3506494 | F12: =MIN($H$5,$E$8+(A12-$H$6)*$H$4) -> 3.45 | G12: =(A12-$H$6)/$B$4 -> 1.2777778 | H12: =IF(G12<=0,$B$6,($B$6+$B$5)*$B$7+MAX(0,G12-1)*2*$B$5*$B$7+$B$5) -> 0.93748696 | I12: =10/C12 -> 3.9113429 | J12: =H12/C12 -> 0.36668329
A13: 20 | B13: =1+($E$5-1)*(A13-$H$6)/($H$7-$H$6) -> 0.96666667 | C13: =$E$4*B13 -> 2.5133333 | D13: =C13-$E$6 -> 0.21333333 | E13: =IF(D13>0,$E$7/D13,"못 벗어남 · 점프") -> 11.25 | F13: =MIN($H$5,$E$8+(A13-$H$6)*$H$4) -> 3.7 | G13: =(A13-$H$6)/$B$4 -> 2.5555556 | H13: =IF(G13<=0,$B$6,($B$6+$B$5)*$B$7+MAX(0,G13-1)*2*$B$5*$B$7+$B$5) -> 1.569287 | I13: =10/C13 -> 3.9787798 | J13: =H13/C13 -> 0.62438473
A14: 25 | B14: =1+($E$5-1)*(A14-$H$6)/($H$7-$H$6) -> 0.95 | C14: =$E$4*B14 -> 2.47 | D14: =C14-$E$6 -> 0.17 | E14: =IF(D14>0,$E$7/D14,"못 벗어남 · 점프") -> 14.117647 | F14: =MIN($H$5,$E$8+(A14-$H$6)*$H$4) -> 3.95 | G14: =(A14-$H$6)/$B$4 -> 3.8333333 | H14: =IF(G14<=0,$B$6,($B$6+$B$5)*$B$7+MAX(0,G14-1)*2*$B$5*$B$7+$B$5) -> 2.201087 | I14: =10/C14 -> 4.048583 | J14: =H14/C14 -> 0.89112832
A15: 30 | B15: =1+($E$5-1)*(A15-$H$6)/($H$7-$H$6) -> 0.93333333 | C15: =$E$4*B15 -> 2.4266667 | D15: =C15-$E$6 -> 0.12666667 | E15: =IF(D15>0,$E$7/D15,"못 벗어남 · 점프") -> 18.947368 | F15: =MIN($H$5,$E$8+(A15-$H$6)*$H$4) -> 4.2 | G15: =(A15-$H$6)/$B$4 -> 5.1111111 | H15: =IF(G15<=0,$B$6,($B$6+$B$5)*$B$7+MAX(0,G15-1)*2*$B$5*$B$7+$B$5) -> 2.832887 | I15: =10/C15 -> 4.1208791 | J15: =H15/C15 -> 1.1673985
A16: 35 | B16: =1+($E$5-1)*(A16-$H$6)/($H$7-$H$6) -> 0.91666667 | C16: =$E$4*B16 -> 2.3833333 | D16: =C16-$E$6 -> 0.083333333 | E16: =IF(D16>0,$E$7/D16,"못 벗어남 · 점프") -> 28.8 | F16: =MIN($H$5,$E$8+(A16-$H$6)*$H$4) -> 4.45 | G16: =(A16-$H$6)/$B$4 -> 6.3888889 | H16: =IF(G16<=0,$B$6,($B$6+$B$5)*$B$7+MAX(0,G16-1)*2*$B$5*$B$7+$B$5) -> 3.464687 | I16: =10/C16 -> 4.1958042 | J16: =H16/C16 -> 1.4537148
A17: 40 | B17: =1+($E$5-1)*(A17-$H$6)/($H$7-$H$6) -> 0.9 | C17: =$E$4*B17 -> 2.34 | D17: =C17-$E$6 -> 0.04 | E17: =IF(D17>0,$E$7/D17,"못 벗어남 · 점프") -> 60 | F17: =MIN($H$5,$E$8+(A17-$H$6)*$H$4) -> 4.7 | G17: =(A17-$H$6)/$B$4 -> 7.6666667 | H17: =IF(G17<=0,$B$6,($B$6+$B$5)*$B$7+MAX(0,G17-1)*2*$B$5*$B$7+$B$5) -> 4.096487 | I17: =10/C17 -> 4.2735043 | J17: =H17/C17 -> 1.7506355
A18: 45 | B18: =1+($E$5-1)*(A18-$H$6)/($H$7-$H$6) -> 0.88333333 | C18: =$E$4*B18 -> 2.2966667 | D18: =C18-$E$6 -> -0.0033333333 | E18: =IF(D18>0,$E$7/D18,"못 벗어남 · 점프") -> 못 벗어남 · 점프 | F18: =MIN($H$5,$E$8+(A18-$H$6)*$H$4) -> 4.95 | G18: =(A18-$H$6)/$B$4 -> 8.9444444 | H18: =IF(G18<=0,$B$6,($B$6+$B$5)*$B$7+MAX(0,G18-1)*2*$B$5*$B$7+$B$5) -> 4.728287 | I18: =10/C18 -> 4.3541364 | J18: =H18/C18 -> 2.0587606
A19: 50 | B19: =1+($E$5-1)*(A19-$H$6)/($H$7-$H$6) -> 0.86666667 | C19: =$E$4*B19 -> 2.2533333 | D19: =C19-$E$6 -> -0.046666667 | E19: =IF(D19>0,$E$7/D19,"못 벗어남 · 점프") -> 못 벗어남 · 점프 | F19: =MIN($H$5,$E$8+(A19-$H$6)*$H$4) -> 5.2 | G19: =(A19-$H$6)/$B$4 -> 10.222222 | H19: =IF(G19<=0,$B$6,($B$6+$B$5)*$B$7+MAX(0,G19-1)*2*$B$5*$B$7+$B$5) -> 5.360087 | I19: =10/C19 -> 4.4378698 | J19: =H19/C19 -> 2.3787368
A20: 55 | B20: =1+($E$5-1)*(A20-$H$6)/($H$7-$H$6) -> 0.85 | C20: =$E$4*B20 -> 2.21 | D20: =C20-$E$6 -> -0.09 | E20: =IF(D20>0,$E$7/D20,"못 벗어남 · 점프") -> 못 벗어남 · 점프 | F20: =MIN($H$5,$E$8+(A20-$H$6)*$H$4) -> 5.45 | G20: =(A20-$H$6)/$B$4 -> 11.5 | H20: =IF(G20<=0,$B$6,($B$6+$B$5)*$B$7+MAX(0,G20-1)*2*$B$5*$B$7+$B$5) -> 5.991887 | I20: =10/C20 -> 4.5248869 | J20: =H20/C20 -> 2.7112611
A21: 60 | B21: =1+($E$5-1)*(A21-$H$6)/($H$7-$H$6) -> 0.83333333 | C21: =$E$4*B21 -> 2.1666667 | D21: =C21-$E$6 -> -0.13333333 | E21: =IF(D21>0,$E$7/D21,"못 벗어남 · 점프") -> 못 벗어남 · 점프 | F21: =MIN($H$5,$E$8+(A21-$H$6)*$H$4) -> 5.7 | G21: =(A21-$H$6)/$B$4 -> 12.777778 | H21: =IF(G21<=0,$B$6,($B$6+$B$5)*$B$7+MAX(0,G21-1)*2*$B$5*$B$7+$B$5) -> 6.623687 | I21: =10/C21 -> 4.6153846 | J21: =H21/C21 -> 3.0570863
A22: 65 | B22: =1+($E$5-1)*(A22-$H$6)/($H$7-$H$6) -> 0.81666667 | C22: =$E$4*B22 -> 2.1233333 | D22: =C22-$E$6 -> -0.17666667 | E22: =IF(D22>0,$E$7/D22,"못 벗어남 · 점프") -> 못 벗어남 · 점프 | F22: =MIN($H$5,$E$8+(A22-$H$6)*$H$4) -> 5.95 | G22: =(A22-$H$6)/$B$4 -> 14.055556 | H22: =IF(G22<=0,$B$6,($B$6+$B$5)*$B$7+MAX(0,G22-1)*2*$B$5*$B$7+$B$5) -> 7.255487 | I22: =10/C22 -> 4.7095761 | J22: =H22/C22 -> 3.4170268
... A29: 100 | B29: =1+($E$5-1)*(A29-$H$6)/($H$7-$H$6) -> 0.7 | C29: =$E$4*B29 -> 1.82 | D29: =C29-$E$6 -> -0.48 | E29: =IF(D29>0,$E$7/D29,"못 벗어남 · 점프") -> 못 벗어남 · 점프 | F29: =MIN($H$5,$E$8+(A29-$H$6)*$H$4) -> 7.5 | G29: =(A29-$H$6)/$B$4 -> 23 | H29: =IF(G29<=0,$B$6,($B$6+$B$5)*$B$7+MAX(0,G29-1)*2*$B$5*$B$7+$B$5) -> 11.678087 | I29: =10/C29 -> 5.4945055 | J29: =H29/C29 -> 6.4165313
A31: 꼬리 길이 = 선두 중심에서 마지막 젤리 끝까지의 경로 길이(일직선 기준). 실제 음식 크기가 섞이면 ±10% 정도 달라진다.
A32: 작은 은신처(30cm)와 긴 은신 통로(100cm)의 내부 경로 길이는 이 표의 30cm·100cm 행 꼬리 길이보다 길어야 한다. E열: 끌림이 최대가 된 뒤 영역 길이만큼 걸어서 벗어나는 시간. 못 벗어나는 길이부터는 점프로 빠져나오거나, 붙잡힌 뒤 이동 키 유지로 탈출한다.

Sheet 예고시간점검
A1: 예고 시간 점검 (기획서 09장: 짧을 때만 피할 수 있는 예고라면 100cm 무리 기준으로 다시 조정)
A2: 필요 시간 = (위험 영역 길이 + 꼬리 길이) ÷ 걷기 속도. 예고가 시작될 때 꼬리가 영역에 막 들어온 최악의 경우다(달리기 없음). 청소기는 선두가 끌림을 이기고 걸어서 벗어나는 시간을 본다.
A4: 위험 | B4: 예고·유예 (초) | C4: 영역 길이 (u) | D4: 필요 · 10cm (초) | E4: 필요 · 50cm (초) | F4: 필요 · 100cm (초) | G4: 100cm 여유 (초) | H4: 판정 | I4: 참고 파라미터 | J4: 메모
A5: 직원 발 착지 | B5: =INDEX(조정값!$G$2:$G$170,MATCH("STF_WARN",조정값!$A$2:$A$170,0)) -> 1.5 | C5: =INDEX(조정값!$G$2:$G$170,MATCH("STF_FOOT_L",조정값!$A$2:$A$170,0)) -> 1.6 | D5: =(C5+INDEX(길이별수치!$H$11:$H$29,MATCH(10,길이별수치!$A$11:$A$29,0)))/INDEX(길이별수치!$C$11:$C$29,MATCH(10,길이별수치!$A$11:$A$29,0)) -> 0.73076923 | E5: =(C5+INDEX(길이별수치!$H$11:$H$29,MATCH(50,길이별수치!$A$11:$A$29,0)))/INDEX(길이별수치!$C$11:$C$29,MATCH(50,길이별수치!$A$11:$A$29,0)) -> 3.088796 | F5: =(C5+INDEX(길이별수치!$H$11:$H$29,MATCH(100,길이별수치!$A$11:$A$29,0)))/INDEX(길이별수치!$C$11:$C$29,MATCH(100,길이별수치!$A$11:$A$29,0)) -> 7.2956522 | G5: =B5-F5 -> -5.7956522 | H5: =IF(G5>=0,"100cm도 피할 수 있음","예고 부족 · 꼬리 일부 손실") -> 예고 부족 · 꼬리 일부 손실 | I5: STF_WARN / STF_FOOT_L | J5: 발 그림자 예고. 발 길이 기준
A6: 세일 매대 붕괴 | B6: =INDEX(조정값!$G$2:$G$170,MATCH("FST_WARN",조정값!$A$2:$A$170,0)) -> 0.5 | C6: =1.6+2*INDEX(조정값!$G$2:$G$170,MATCH("FST_ZONE_MARGIN",조정값!$A$2:$A$170,0)) -> 3.6 | D6: =(C6+INDEX(길이별수치!$H$11:$H$29,MATCH(10,길이별수치!$A$11:$A$29,0)))/INDEX(길이별수치!$C$11:$C$29,MATCH(10,길이별수치!$A$11:$A$29,0)) -> 1.5 | E6: =(C6+INDEX(길이별수치!$H$11:$H$29,MATCH(50,길이별수치!$A$11:$A$29,0)))/INDEX(길이별수치!$C$11:$C$29,MATCH(50,길이별수치!$A$11:$A$29,0)) -> 3.97637 | F6: =(C6+INDEX(길이별수치!$H$11:$H$29,MATCH(100,길이별수치!$A$11:$A$29,0)))/INDEX(길이별수치!$C$11:$C$29,MATCH(100,길이별수치!$A$11:$A$29,0)) -> 8.3945533 | G6: =B6-F6 -> -7.8945533 | H6: =IF(G6>=0,"100cm도 피할 수 있음","예고 부족 · 꼬리 일부 손실") -> 예고 부족 · 꼬리 일부 손실 | I6: FST_WARN / 낙하 폭 1.6 + 여유 | J6: 낙하 지점 폭(대표 1.6u)을 가로질러 벗어나는 기준. 실제로는 반대편 통로로 우회
A7: 과일 무더기 | B7: =INDEX(조정값!$G$2:$G$170,MATCH("FRT_WARN",조정값!$A$2:$A$170,0)) -> 1 | C7: =INDEX(조정값!$G$2:$G$170,MATCH("FRT_LANE_W",조정값!$A$2:$A$170,0)) -> 1.2 | D7: =(C7+INDEX(길이별수치!$H$11:$H$29,MATCH(10,길이별수치!$A$11:$A$29,0)))/INDEX(길이별수치!$C$11:$C$29,MATCH(10,길이별수치!$A$11:$A$29,0)) -> 0.57692308 | E7: =(C7+INDEX(길이별수치!$H$11:$H$29,MATCH(50,길이별수치!$A$11:$A$29,0)))/INDEX(길이별수치!$C$11:$C$29,MATCH(50,길이별수치!$A$11:$A$29,0)) -> 2.9112812 | F7: =(C7+INDEX(길이별수치!$H$11:$H$29,MATCH(100,길이별수치!$A$11:$A$29,0)))/INDEX(길이별수치!$C$11:$C$29,MATCH(100,길이별수치!$A$11:$A$29,0)) -> 7.075872 | G7: =B7-F7 -> -6.075872 | H7: =IF(G7>=0,"100cm도 피할 수 있음","예고 부족 · 꼬리 일부 손실") -> 예고 부족 · 꼬리 일부 손실 | I7: FRT_WARN / FRT_LANE_W | J7: 레인 폭 가로지르기
A8: 청소기 영역 걸어서 탈출 (선두) | B8: =INDEX(조정값!$G$2:$G$170,MATCH("VAC_PULL_RAMP",조정값!$A$2:$A$170,0)) -> 1.5 | C8: =INDEX(조정값!$G$2:$G$170,MATCH("VAC_ZONE_L",조정값!$A$2:$A$170,0)) -> 2.4 | D8: =IF(INDEX(길이별수치!$D$11:$D$29,MATCH(10,길이별수치!$A$11:$A$29,0))>0,C8/INDEX(길이별수치!$D$11:$D$29,MATCH(10,길이별수치!$A$11:$A$29,0)),999) -> 8 | E8: =IF(INDEX(길이별수치!$D$11:$D$29,MATCH(50,길이별수치!$A$11:$A$29,0))>0,C8/INDEX(길이별수치!$D$11:$D$29,MATCH(50,길이별수치!$A$11:$A$29,0)),999) -> 999 | F8: =IF(INDEX(길이별수치!$D$11:$D$29,MATCH(100,길이별수치!$A$11:$A$29,0))>0,C8/INDEX(길이별수치!$D$11:$D$29,MATCH(100,길이별수치!$A$11:$A$29,0)),999) -> 999 | G8: =IF(F8<999,B8-F8,"—") -> — | H8: =IF(F8<999,"걸어서 탈출 가능","걸어서는 못 벗어남 · 점프 또는 붙잡힌 뒤 탈출") -> 걸어서는 못 벗어남 · 점프 또는 붙잡힌 뒤 탈출 | I8: VAC_PULL_RAMP / VAC_ZONE_L / VAC_LEADER_PULL_MAX | J8: 최대 끌림 기준. 999 = 걷기가 끌림보다 느림. 실패는 없고 붙잡히면 이동 키 1.8초 유지로 탈출(LDR_ESCAPE_HOLD)
A11: 값이 빨간 줄은 '100cm 무리는 꼬리 일부를 잃는다'는 뜻이다. 우회로가 있는 위험은 의도한 난도로 본다. 예고를 늘릴지, 배치를 바꿀지는 처음 하는 사람 기준 플레이테스트에서 정한다.

Sheet 변경기록
A1: 날짜 | B1: 버전 | C1: ID | D1: 이전 값 | E1: 새 값 | F1: 이유 | G1: 작성
A2: 2026-09-28 | B2: 1.0 | C2: (전체) | F2: 초안. 프로토타입 v3.1 코드 값과 기획서 v0.3 값을 옮기고, 9/28 결정(6구역·달리기 1.6·은신처 2종)을 반영 | G2: 정예원
A3: 2026-09-28 | B3: 1.0 | C3: LDR_RUN_MULT | D3: 1.9 | E3: 1.6 | F3: 기획서 값으로 맞춤. 걷기 2.6 기준 10cm 달리기 4.16u/s (v3.1 이전 4.18과 거의 같음) | G3: 정예원
A4: 2026-09-30 | B4: 1.1 | C4: (전체) | F4: 기획서 v0.4·시스템기획서 v1.1에 맞춤. 현재 적용값 = 그레이박스 코드(101CM_Game) 값. 구역 시트 7구역, 음식 목록에 좌표·높이 추가, 길이별수치·예고시간점검을 달리기 없는 규칙으로 다시 계산 | G4: 정예원
A5: 2026-09-30 | B5: 1.1 | C5: LDR_RUN_* (4개) | D5: 1.6 / 2.5 / 4 / 0.8 | E5: 삭제 | F5: 9/29: 달리기 삭제, Shift = 점프 | G5: 정예원
A6: 2026-09-30 | B6: 1.1 | C6: LDR_JUMP_HEIGHT 외 3개 | D6: — | E6: 1.15 / 0.12 / 0.15 / 1.7 | F6: 점프 추가 (높이 체계 0.5·0.95·1.0·2.0) | G6: 정예원
A7: 2026-09-30 | B7: 1.1 | C7: LDR_EAT_RANGE | D7: 1 (몸길이) | E7: LDR_EAT_RING 0.625 + MARGIN 0.15 | F7: 9/29: 먹기 판정을 발밑 링 안으로 좁힘 | G7: 정예원
A8: 2026-09-30 | B8: 1.1 | C8: JLY_RECOVER_RANGE | D8: 1 (몸길이) | E8: 삭제 | F8: 회수도 발밑 링 + Space, 한 마리씩 | G8: 정예원
A9: 2026-09-30 | B9: 1.1 | C9: CHN_FOLLOW_MAX | D9: 1.7 (× 달리기) | E9: CHN_CATCHUP 3.2 (× 걷기) | F9: 궤적 추종으로 변경 | G9: 정예원
A10: 2026-09-30 | B10: 1.1 | C10: CHN_REVERT | D10: — | E10: 5 | F10: 9/29: 떨어진 동료는 5초 뒤 음식으로 | G10: 정예원
A11: 2026-09-30 | B11: 1.1 | C11: FST_WARN | D11: 1 | E11: 0.5 | F11: 9/29: 긴장감을 위해 떨림 단축 | G11: 정예원
A12: 2026-09-30 | B12: 1.1 | C12: FST_LIVE | D12: 2.5 | E12: 1.6 | F12: 그레이박스 조정 | G12: 정예원
A13: 2026-09-30 | B13: 1.1 | C13: FST_RESET · FST_REARM | D13: 테스트용 | E13: 확정 | F13: 저장이 없으므로 반복 작동을 정식 규칙으로 | G13: 정예원
A14: 2026-09-30 | B14: 1.1 | C14: VAC_ZONE_L | D14: 2.6 | E14: 2.4 | F14: 9/29: 흡입 영역 축소. Z4 문 앞은 1.6×1.7 | G14: 정예원
A15: 2026-09-30 | B15: 1.1 | C15: VAC_SPEED · VAC_PAUSE | D15: 1.2 / 1.5 | E15: 1.1 / 1.2 | F15: 레벨 빌더 씬 값 | G15: 정예원
A16: 2026-09-30 | B16: 1.1 | C16: VAC_LEADER_PULL | D16: 1.4 | E16: 1.5 → 최대 2.3 (1.5초) | F16: 오래 머물수록 세짐 | G16: 정예원
A17: 2026-09-30 | B17: 1.1 | C17: LDR_ESCAPE_* (4개) | D17: — | E17: 1.8 / 0.4 / 6.5 / 2 | F17: 9/29: 청소기 실패 삭제 → 이동 키 유지로 탈출 (연타 없음) | G17: 정예원
A18: 2026-09-30 | B18: 1.1 | C18: FRT_SPEED · FRT_LANE_W | D18: 2 / 1 | E18: 4.2 / 1.2 | F18: 과일 무더기로 구현 | G18: 정예원
A19: 2026-09-30 | B19: 1.1 | C19: ROL_* · SRF_* · ICE_* | D19: — | E19: 신규 | F19: 굴러다니는 물건, 바닥 방해, 얼음 추가 | G19: 정예원
A20: 2026-09-30 | B20: 1.1 | C20: DET_* (11개) · HID_CHECK_INTERVAL | D20: — | E20: 삭제 | F20: 9/29: 직원 감지·은신 판정 삭제 | G20: 정예원
A21: 2026-09-30 | B21: 1.1 | C21: GAM_CHECKPOINTS | D21: 5 | E21: 삭제 → GAM_ZONE_SIGNS 5 | F21: 9/29: 저장 삭제, 구역 안내판으로 | G21: 정예원
A22: 2026-09-30 | B22: 1.1 | C22: GAM_ZONES | D22: 6 | E22: 7 | F22: 카운터와 골 홀 분리, 34×41 ㄹ자 | G22: 정예원
A23: 2026-09-30 | B23: 1.1 | C23: GAM_RESULT_DELAY | D23: 6 | E23: 3.5 | F23: 현재 코드 값. 실루엣 연출을 넣을 때 조정 | G23: 정예원
A24: 2026-09-30 | B24: 1.1 | C24: GAM_PLAYTIME | D24: 60 | E24: (비움) | F24: 맵 축소 후 재측정 | G24: 정예원
